done
torch.Size([59850, 64, 64])
torch.Size([59850, 64, 64])
18028225
training...
Traceback (most recent call last):
  File "/home/gridsan/agoertzen/dissipativity/FNO_a/NSE_FNO.py", line 84, in <module>
    u_pred2 = model(x_batch)#.unsqueeze(1)
  File "/home/gridsan/agoertzen/.local/lib/python3.9/site-packages/torch/nn/modules/module.py", line 1518, in _wrapped_call_impl
    return self._call_impl(*args, **kwargs)
  File "/home/gridsan/agoertzen/.local/lib/python3.9/site-packages/torch/nn/modules/module.py", line 1527, in _call_impl
    return forward_call(*args, **kwargs)
  File "/home/gridsan/agoertzen/dissipativity/FNO_a/fno_2d.py", line 141, in forward
    x = self.conv1(x)
  File "/home/gridsan/agoertzen/.local/lib/python3.9/site-packages/torch/nn/modules/module.py", line 1518, in _wrapped_call_impl
    return self._call_impl(*args, **kwargs)
  File "/home/gridsan/agoertzen/.local/lib/python3.9/site-packages/torch/nn/modules/module.py", line 1527, in _call_impl
    return forward_call(*args, **kwargs)
  File "/home/gridsan/agoertzen/dissipativity/FNO_a/fno_2d.py", line 115, in forward
    x1 = self.conv3(x, size_list[4])
  File "/home/gridsan/agoertzen/.local/lib/python3.9/site-packages/torch/nn/modules/module.py", line 1518, in _wrapped_call_impl
    return self._call_impl(*args, **kwargs)
  File "/home/gridsan/agoertzen/.local/lib/python3.9/site-packages/torch/nn/modules/module.py", line 1527, in _call_impl
    return forward_call(*args, **kwargs)
  File "/home/gridsan/agoertzen/dissipativity/FNO_a/fno_2d.py", line 56, in forward
    x = torch.fft.irfftn(out_ft, s=(size, size), dim=[2,3], norm="ortho")
torch.cuda.OutOfMemoryError: CUDA out of memory. Tried to allocate 2.49 GiB. GPU 0 has a total capacty of 31.73 GiB of which 488.25 MiB is free. Including non-PyTorch memory, this process has 31.25 GiB memory in use. Of the allocated memory 28.63 GiB is allocated by PyTorch, and 2.24 GiB is reserved by PyTorch but unallocated. If reserved but unallocated memory is large try setting max_split_size_mb to avoid fragmentation.  See documentation for Memory Management and PYTORCH_CUDA_ALLOC_CONF
<class 'numpy.ndarray'>
Traceback (most recent call last):
  File "/home/gridsan/agoertzen/.local/lib/python3.9/site-packages/scipy/io/matlab/_mio.py", line 39, in _open_file
    return open(file_like, mode), True
FileNotFoundError: [Errno 2] No such file or directory: 'inference/u_rollout.mat'

During handling of the above exception, another exception occurred:

Traceback (most recent call last):
  File "/home/gridsan/agoertzen/dissipativity/FNO_a/statgen.py", line 17, in <module>
    data_model = scipy.io.loadmat('inference/u_rollout.mat')
  File "/home/gridsan/agoertzen/.local/lib/python3.9/site-packages/scipy/io/matlab/_mio.py", line 225, in loadmat
    with _open_file_context(file_name, appendmat) as f:
  File "/state/partition1/llgrid/pkg/anaconda/anaconda3-2023a-pytorch/lib/python3.9/contextlib.py", line 119, in __enter__
    return next(self.gen)
  File "/home/gridsan/agoertzen/.local/lib/python3.9/site-packages/scipy/io/matlab/_mio.py", line 17, in _open_file_context
    f, opened = _open_file(file_like, appendmat, mode)
  File "/home/gridsan/agoertzen/.local/lib/python3.9/site-packages/scipy/io/matlab/_mio.py", line 45, in _open_file
    return open(file_like, mode), True
FileNotFoundError: [Errno 2] No such file or directory: 'inference/u_rollout.mat'
Traceback (most recent call last):
  File "/home/gridsan/agoertzen/.local/lib/python3.9/site-packages/scipy/io/matlab/_mio.py", line 39, in _open_file
    return open(file_like, mode), True
FileNotFoundError: [Errno 2] No such file or directory: 'inference/u_1step.mat'

During handling of the above exception, another exception occurred:

Traceback (most recent call last):
  File "/home/gridsan/agoertzen/dissipativity/FNO_a/statgen2.py", line 12, in <module>
    data = scipy.io.loadmat('inference/u_1step.mat')
  File "/home/gridsan/agoertzen/.local/lib/python3.9/site-packages/scipy/io/matlab/_mio.py", line 225, in loadmat
    with _open_file_context(file_name, appendmat) as f:
  File "/state/partition1/llgrid/pkg/anaconda/anaconda3-2023a-pytorch/lib/python3.9/contextlib.py", line 119, in __enter__
    return next(self.gen)
  File "/home/gridsan/agoertzen/.local/lib/python3.9/site-packages/scipy/io/matlab/_mio.py", line 17, in _open_file_context
    f, opened = _open_file(file_like, appendmat, mode)
  File "/home/gridsan/agoertzen/.local/lib/python3.9/site-packages/scipy/io/matlab/_mio.py", line 45, in _open_file
    return open(file_like, mode), True
FileNotFoundError: [Errno 2] No such file or directory: 'inference/u_1step.mat'
